# 예외처리(exception handling)
## 프로그램 오류
프로그램이 실행 중 어떤 원인에 의해서 오작동을 하거나 비정상적으로 종료되는 경우가 있다.
이러한 결과를 초래하는 원인을 프로그램 에러 또는 오류라고 한다.
- 발생시점에 따라 '컴파일에러'와 '런타임에러'로 나눌 수 있다.
- 컴파일 에러 : 컴파일 시에 발생하는 에러
- 런타임 에러 : 실행 시에 발생하는 에러
- 논리적 에러 : 실행은 되지만, 의도와 다르게 동작하는 것.

> 소스코드를 컴파일 하면 컴파일러가 소스코드(.java)에 대해 오타나 잘못된 구문, 자료형 체크 등의 기본적인 검사를 수행하여 오류가 있는지를 알려준다.
컴파일러가 알려 준 에러들을 모두 수정해서 컴파일을 성공적으로 마치고 나면, 클래스 파일(.class)이 생성되고, 생성된 클래스 파일을 실행할 수 있게 되는 것이다.

컴파일이 에러없이 성공적으로 마쳤다고 해서 프로그램의 실행 시에도 에러가 발생하지 않는 것은 아니다.
컴파일러가 소스코드의 기본적인 사항은 컴파일 시에 모두 걸러줄 수는 있지만, 실행도중에 발생할 수 있는 잠재적인 오류까지 검사할 수 없기 때문에 컴파일은 잘되었어도 실행 중에 에러에 의해서 잘못된 결과를 얻거나 프로그램이 비정상적으로 종료될 수 있다.
- 이러한 실행 중에 발생한 에러 즉, 런타임 에러를 방지하기 위해서는 프로그램의 실행도중 발생할 수 있는 모든 경우의 수를 고려하여 이에 대한 대비를 하는 것이 필요하다.
- 자바에서는 실행 시(runtime) 발생할 수 있는 프로그램 오류를 '에러(error)'와 '예외(exception)', 두 가지로 구분 하였다.
    - **에러**는 메모리부족(OutOfMemoryError)이나 스택오버플로우(StackOveflowError)와 같이 일단 발생하면 복구할 수 없는 심각한 오류
    - **예외**는 발생하더라도 수습될 수 있는 다소 미약한 오류

## 예외 클래스 계층구조
모든 예외의 최고 조상은 Exception 클래스이다.

- Exception 클래스들 : 사용자의 실수와 같은 외적인 요인에 의해 발생하는 예외
- RuntimeException 클래스들 : 프로그래머의 실수로 발생하는 예외

RuntimeException클래스들은 주로 프로그래머의 실수에 의해서 발생될 수 있는 예외들로 자바의 프로그래밍 요소들과 관계가 깊다.

- 예를 들어 배열의 범위를 벗어난다던가(ArrayIndexOutOfBoundsException), 값이 null인 참조변수의 멤버의 호출하려고 했다던가(NullPointerException), 클래스 간의 형변환을 잘못했다던가(ClassCastException), 정수를 0으로 나누려고(ArithmeticException)하는 경우에 발생한다.

## 예외처리하기 try-catch문
프로그램의 실행도중에 발생하는 에러는 어쩔 수 없지만, 예외는 프로그래머가 이에 대한 처리를 미리해주어야한다.
- 예외처리의 목적은 예외의 발생으로 인한 실행 중인 프로그램의 갑작스런 비정상 종료를 막고, 정상적인 실행상태를 유지할 수 있도록 하는 것이다.

예외처리
- 정의 : 프로그램 실행 시 발생할 수 있는 예외에 대비한 코드를 작성하는 것.
- 목적 : 프로그램의 비정상적인 종료를 막고, 정상적인 실행상태를 유지하는 것.

> 발생한 예외를 처리하지 못하면, 프로그램은 비정상적으로 종료되며, 처리되지 못한 예외(uncaught exception)는 JVM의 '예외처리기(UncaughtExceptionHandler)'가 받아서 예외의 원인을 화면에 출력한다.

예외를 처리하기 위해서는 try-catch문을 사용한다.
~~~java
    try{
        //예외가 발생할 가능성이 있는 문장들을 넣는다.
    }catch(Exception1 e1){
        //Exception1이 발생했을 경우 이를 처리하기 위한 문장을 적는다.
    }catch(Exception2 e2){
        //Exception2이 발생했을 경우 이를 처리하기 위한 문장을 적는다.
    }
~~~
발생한 예외의 종류와 일치하는 단 한 개의 catch블럭만 수행되며, 발생한 예외의 종류와 일치하는 catch블럭이 없으면 예외는 처리되지 않는다.
- 하나의 메서드 내에 여러 개의 try-catch문이 사용될 수 있다.
- try블럭 또는 catch블럭에 또 다른 try-catch문이 포함될 수 있다.
- try-catch문에서의 흐름
    - try블럭 내에서 예외가 발생한 경우
        1. 발생한 예외와 일치하는 catch블럭이 있는지 확인한다.
        2. 일치하는 catch블럭을 찾게 되면, 그 catch블럭 내의 문장들을 수행하고 전체 try-catch문을 빠져나가서 그 다음 문장을 계속해서 수행한다. 만일 일치하는 catch블럭을 찾지 못하면, 예외는 처리되지 못한다.
    -  try블럭 내에서 예외가 발생하지 않은 경우
        1. catch블럭을 거치지 않고 전체 try-catch문을 빠져나가서 수행을 계속한다.  

### **예외의 발생과 catch블럭**
catch블럭은 괄호()와 블럭{} 두 부분으로 나눠져 있는데, 괄호()내에는 처리하고자 하는 예외와 같은 타입의 참조변수 하나를 선언해야한다.
- 예외가 발생하면, **발생한 예외에 해당하는 클래스의 인스턴스가 만들어 진다.**
- 예외가 발생하면, 첫 번째 catch블럭부터 차례로 내려가면서 catch블럭의 괄호()내에 선언된 참조변수의 종류와 생성된 예외클래스의 인스턴스에 instanceof연산자를 이용해서 검사하게 되는데, 검사결과가 true인 catch블럭을 만날 때까지 검사는 계속된다.

> 모든 예외 클래스는 Exception클래스의 자손이므로, catch블럭의 괄호()에 Exception클래스 타입의 참조변수를 선언해 놓으면 어떤 종류의 예외가 발생하더라도 이 catch블럭에 의해서 처리된다.

## printStackTrace()와 getMessage()
예외가 발생했을 때 생성되는 예외 클래스의 인스턴스에는 발생한 예외에 대한 정보가 담겨 있으며, getMessage()와 printStackTrace()를 통해서 이 정보들을 얻을 수 있다.
- printStackTrace() : 예외발생 당시의 호출스택(Call Stack)에 있었던 메서드의 정보와 예외 메시지들 화면에 출력한다.
- getMessage() : 발생한 예외클래스의 인스턴스에 저장된 메시지를 얻을 수 있다.

## 멀티 catch블럭
JDK1.7부터 여러 catch블럭을 '|'기호를 이용해서, 하나의 catch블럭으로 합칠 수 있게 되었으며, 이를 '멀티 catch블럭"이라 한다.
~~~java
    try{
        ...
    }catch(Exception1 e1){
        e1.printStackTrace();
    }catch(Exception2 e2){
        e2.printStackTrace();
    }

    //위의 catch문을 멀티 catch블럭을 이용해서 줄일 수 있다.
    try{
        ...
    }catch(Exception1 | Exception2 e){ //멀티 catch블럭 사용
        e.printStackTrace():
    }
~~~ 
- '|' 기호로 연결할 수 있는 예외 클래스의 개수에는 제한이 없다.
- 중복된 코드를 줄일 수 있다.
- 멀티 catch블럭에 선언된 참조변수 e는 실제로 어떤 예외가 발생한지 알 수 없으므로, 연결된 예외 클래스들의 공통 분모인 조상 예외 클래스에 선언된 멤버만 사용할 수 있다.
📌 '|' 기호로 연결된 예외 클래스가 조상과 자손의 관계에 있다면 컴파일 에러가 일어난다. 이것은 조상클래스만 써주는 것과 같기 때문에 불필요한 코드를 제거하라는 의미로 에러가 발생한다.

## 예외 발생시키기
키워드 throw를 사용해서 프로그래머가 고의로 예외를 발생시킬 수 있다.
1. 연산자 new를 이용해서 발생시키려는 예외 클래스의 객체를 만든다음.
~~~java
    Exception e = new Exception("고의로 발생시켰다");
~~~
2. 키워드 throw를 이용해서 예외를 발생시킨다.
~~~java
    throw e;
~~~
한 줄로 줄여서 쓸 수도 있다.
~~~java
    throw new Exception("예외발생시키기");
~~~

Exception인스턴스를 생성할 때, 생성자에 String을 넣어주면, 이 String이 Exception인스턴스에 메시지로 저장되고 이 메시지는 getMessage()를 이용해서 얻을 수 있다.

> Exception클래스와 그 자손들은 예외처리를 해주지않으면 컴파일 에러가 난다. 하지만 RuntimeException클래스와 그 자손에 해당하는 예외는 프로그래머에 의해 실수로 발생하는 것들이기 때문에 예외처리를 강제하지 않는다. -> 예외처리를 하지 않아도 컴파일 에러는 나지않지만 비정상적으로 종료된다.
- 컴파일러가 예외처리를 확인하지 않는 RuntimeException클래스들은 'unchecked예외'라고 부르고, 예외처리를 확인하는 Exception클래스들은 'checked예외'라고 부른다.

## 메서드에 예외 선언하기
예외를 처리하는 방법에는 지금까지 배워온 try-catch문을 사용하는 것 외에, 예외를 메서드에 선언하는 방법이 있다.
- 메서드에 예외를 선언하려면, 메서드의 선언부에 키워드 **throws**를 사용해서 메서드 내에서 발생할 수 있는 예외를 적어주기만 하면 된다.
- 그리고 예외가 여러 개일 경우에는 쉼표(,)로 구분한다.
~~~java
    void method() throws Exception1, Exception2, ... ExceptionN{
        //메서드 내용
    }
~~~
- 메서드의 선언부에 예외를 선언함으로써 메서드를 사용하려는 사람이 메서드의 선언부를 보았을 때, 이 메서드를 사용하기 위해서는 어떠한 예외들이 처리되어져야 하는지 쉽게 알 수 있다.
- 사실 예외를 메서드의 throws에 명시하는 것은 예외를 처리하는 것이 아니라, 자신(예외가 발생할 가능성이 있는 메서드)을 호출한 메서드에게 **예외를 전달하여 예외처리를 떠맡기는 것이다.** 

### finally 블럭
finally블럭은 예외의 발생여부에 상관없이 실행되어야할 코드를 포함시킬 목적으로 사용된다.
- try-catch문의 끝에 선택적으로 덧붙여 사용할 수 있다.
~~~java
    try{
        //예외가 발생할 가능성이 있는 문장을 작성
    }catch(Exception1 e1){
        //예외처리를 위한 문장
    }finally{
        //예외의 발생여부에 관계없이 항상 수행되어야하는 문장들을 넣는다.
    }
~~~
📌 try블럭 또는 catch블럭에서 return문이 실행되는 경우에도 finally블럭의 문장들이 먼저 실행된 후에, 현재 실행 중인 메서드를 종료한다.

## 자동 자원 반환 : try-with-resource문
JDK1.7부터 try-with-resource문이라는 try-catch문의 변형이 새로 추가되었다.
- 이 구문은 주로 '입출력(I/O)'과 관련된 클래스를 사용할 때 유용하다.
- 사용한 후에 꼭 닫아줘야하는 것들에 사용한다. 그래야 자원(resource)이 반환되기 때문이다.
- **try-with-resource문의 괄호()안에 객체를 생성하는 문장을 넣으면, 이 객체는 따로 close()를 호출하지 않아도 try블럭을 벗어나는 순간 자동적으로 close()가 호출된다.**
- 그 다음에 catch블럭 또는 finally블럭이 수행된다.
~~~java
    //괄호()안에 두 문장 이상 넣을 경우 ';'로 구분한다.
    try(FileInputStream fis = new FileInputStream("score.dat");
        DataInputStream dis = new DataInputStream(fis)){
            while(true){
                score = dis.readInt();
                System.out.println(score);
                sum += score;
            }
    }catch(EOFException e){
        System.out.println("점수의 총합은 "+ sum + "입니다.");
    }catch(IOException ie){
        ie.printStackTrace();
    }
~~~
- 위의 예시 처럼 try블럭의 괄호안에 변수를 선언하는 것도 가능하며, 선언된 변수는 try블럭 내에서만 사용할 수 있다.

이처럼 try-with-resource문에 의해 자동으로 객체의 close()가 호출될 수 있으려면 클래스가 **AutoCloseable**이라는 인터페이스를 구현한 것이어야만 한다.
- AutoCloseable인터페이스는 각 클래스에서 적절히 자원 반환작업을 하도록 구현되어 있다.

## 사용자정의 예외 만들기
기존의 정의된 예외 클래스 외에 필요에 따라 프로그래머가 새로운 예외 클래스를 정의하여 사용할 수 있다.
- Exception클래스나 RuntimeException클래스로부터 상속받아 클래스를 만들지만, 필요에 따라서 알맞은 예외 클래스를 선택할 수 있다.

## 예외 되던지기(exception re-throwing)
단 하나의 예외에 대해서도 예외가 발생한 메서드와 호출한 메서드, 양쪽에서 처리하도록 할 수 있다.
- 이것은 예외를 처리한 후에 인위적으로 다시 발생시키는 방법을 통해서 가능한데, 이것을 '예외 되던지기(exception re-throwing)'라고 한다.
- 먼저 예외가 발생할 가능성이 있는 메서드에서 try-catch문을 사용해서 예외를 처리해주고 catch문에서 필요한 작업을 행한 후에 throw문을 사용해서 예외를 다시 발생시킨다.
- 다시 발생한 예외는 이 메서드를 호출한 메서드에게 전달되고 호출한 메서드의 try-catch문에서 또 다시 예외를 처리한다.

> 주의 할 점은 예외가 발생할 메서드에서는 try-catch문을 사용해서 예외처리를 해줌과 동시에 메서드의 선언부에 발생할 예외를 throws에 지정해줘야한다.

## 연결된 예외(chained exception)
한 예외가 다른 예외를 발생시킬 수도 있다. 예외A가 예외B를 발생시켰다면, A를 B의 '원인 예외(cause exception)'라고 한다.
- Throwable initCause(Throwable cause) : 지정한 예외를 원인 예외로 등록
- Throwable getCause() : 원인 예외를 반환.
    - Throwable은 Exception클래스의 조상 클래스이므로, 위의 메서드들은 모든 예외에서 사용가능하다.

checked예외를 unchecked예외로 바꾸면 예외처리가 선택적이 되므로 억지로 예외처리를 하지 않아도 되기에 이런 경우 사용하며 또는, 여러가지 예외를 하나의 큰 분류의 예외로 묶어서 다루기 위해서이다.
~~~java
    static void startInstall() throws SpaceException{
        if(!enoughSpace())
            throw new SpaceException("설치할 공간이 부족합니다.");
        if(!enoughMemory)
            throw new RuntimeException(new MemoryException("메모리가 부족합니다."));
    }
~~~
MemoryException은 Exception의 자손이므로 반드시 예외를 처리해야하는데, 이 예외를 RuntimeException으로 감싸버렸기 때문에 unchecked예외가 되었다. 그래서 더 이상 메소드의 선언부에 해당 예외를 선언하지 않아도 되도록 하였다.
- 참고로 위의 코드에서는 initCause() 대신에 RuntimeException의 생성자를 사용한 것이다.